<?xml version="1.0"?>
<!-- This file contains the urdf of the base platform -->
<!-- Description of the robot in URDF format -->
<!-- Each link must have at least visual for rivz -->
<!-- Each link must have inertia and collision for gazebo -->

<robot name="rmitbot" xmlns:xacro="http://ros.org/wiki/xacro">
    
    <link name="base_footprint"/>

    <link name="base_link">
        <inertial>
            <origin xyz="0 0 0" rpy="0.0 0.0 0.0" />
            <mass value="3.824"/> 
            <inertia 
                ixx="0.092" ixy="0.02" ixz="-5.178e-05"
                iyy="0.061" iyz="0" 
                izz="0.145" />
        </inertial>
        <visual>
            <origin xyz="0 0 -0.002" rpy="0 0 0" />
            <geometry>
                <mesh filename="package://rmitbot_description/meshes/base_link.stl" scale="0.001 0.001 0.001"/>
            </geometry>
        </visual>
        <collision>
            <origin xyz="0 0 0.068" rpy="0 0 0" />
            <geometry>
                <box size="0.40 0.38 0.03"/>
            </geometry>
        </collision>
        <collision>
            <origin xyz="0 0 0.023" rpy="0 0 0" />
            <geometry>
                <box size="0.30 0.38 0.065"/>
            </geometry>
        </collision>
    </link>


    <joint name="base_joint" type="fixed">
        <parent link="base_footprint"/>
        <child link="base_link" />
        <origin xyz="0 0 0.052" rpy="0 0 0"/>
    </joint>

    <link name="front_left_wheel">
        <inertial>
            <origin xyz="0 0 0" rpy="0 0 0" />
            <mass value="4.315763" />
            <inertia 
                ixx="5.3947033e-03" ixy="6.821e-17" ixz="-1.137e-17"
                iyy="4.4596211e-03" iyz="0.0" 
                izz="4.4596218e-03" />
        </inertial>
        <visual>
            <origin xyz="-0.02245 0 0" rpy="0 0 0" />
            <geometry>
                <mesh filename="package://rmitbot_description/meshes/front_left_wheel.stl" scale="0.001 0.001 0.001" />
            </geometry>
        </visual>
        <collision>
            <origin xyz="0 0 0" rpy="0 ${pi/2} 0" />
            <geometry>
                <cylinder radius="0.05" length="0.0449"/>
            </geometry>
        </collision>
    </link>

    <joint name="front_left_wheel_joint" type="continuous">
        <origin xyz="-0.18045 0.17 -0.003" rpy="0 0 0" />
        <parent link="base_link" />
        <child link="front_left_wheel" />
        <axis xyz="1 0 0" />
    </joint>

    <link name="rear_left_wheel">
        <inertial>
            <origin xyz="0 0 0" rpy="0 0 0" />
            <mass value="4.315763" />
            <inertia 
                ixx="0.0053947033" ixy="-2.274e-12" ixz="0.0"
                iyy="0.0044596211" iyz="0.0"
                izz="0.0044596218" />
        </inertial>
        <visual>
            <origin xyz="-0.02245 0 0" rpy="0 0 0" />
            <geometry>
                <mesh filename="package://rmitbot_description/meshes/rear_left_wheel.stl" scale="0.001 0.001 0.001"/>
            </geometry>
        </visual>
        <collision>
            <origin xyz="0 0 0" rpy="0 ${pi/2} 0" />
            <geometry>
                <cylinder radius="0.05" length="0.0449"/>
            </geometry>
        </collision>
    </link>


    <joint name="rear_left_wheel_joint" type="continuous">
        <origin xyz="-0.18045 -0.17 -0.003" rpy="0 0 0" />
        <parent link="base_link" />
        <child link="rear_left_wheel" />
        <axis xyz="1 0 0" />
    </joint>

    <link name="front_right_wheel">
        <inertial>
            <origin xyz="0 0 0" rpy="0 0 0" />
            <mass value="4.315763" />
            <inertia 
                ixx="0.0053947033" ixy="2.274e-12" ixz="0.0"
                iyy="0.0044596211" iyz="0.0"
                izz="0.0044596218" />
        </inertial>
        <visual>
            <origin xyz="-0.02245 0 0" rpy="0 0 0" />
            <geometry>
                <mesh filename="package://rmitbot_description/meshes/front_right_wheel.stl" scale="0.001 0.001 0.001"/>
            </geometry>
        </visual>
        <collision>
            <origin xyz="0 0 0" rpy="0 ${pi/2} 0" />
            <geometry>
                <cylinder radius="0.05" length="0.0449"/>
            </geometry>
        </collision>
    </link>

    <joint name="front_right_wheel_joint" type="continuous">
        <origin xyz="0.18045 0.17 -0.003" rpy="0 0 0" />
        <parent link="base_link" />
        <child link="front_right_wheel" />
        <axis xyz="1 0 0" />
    </joint>

    <link name="rear_right_wheel">
        <inertial>
            <origin xyz="0 0 0" rpy="0 0 0" />
            <mass value="4.315763" />
            <inertia 
                ixx="0.0053947033" ixy="-2.274e-12" ixz="0.0"
                iyy="0.0044596211" iyz="0.0"
                izz="0.0044596218" />
        </inertial>
        <visual>
            <origin xyz="-0.02245 0 0" rpy="0 0 0" />
            <geometry>
                <mesh filename="package://rmitbot_description/meshes/rear_right_wheel.stl" scale="0.001 0.001 0.001"/>
            </geometry>
        </visual>
        <collision>
            <origin xyz="0 0 0" rpy="0 ${pi/2} 0" />
            <geometry>
                <cylinder radius="0.05" length="0.0449"/>
            </geometry>
        </collision>
    </link>


    <joint name="rear_right_wheel_joint" type="continuous">
        <origin xyz="0.18045 -0.17 -0.003" rpy="0 0 0" />
        <parent link="base_link" />
        <child link="rear_right_wheel" />
        <axis xyz="1 0 0" />
    </joint>
</robot>